<?xml version="1.0"?>
<robot xmlns:xacro="http://www.ros.org/wiki/xacro" name="ABot">

  <!--<link name="base_footprint">
   </link>

  <joint name="base_footprint_joint" type="fixed">
     <parent link="base_footprint"/>
     <child link="base_link"/>
     <origin xyz="0.00 0.00 0.1" rpy="0.0 0.0 0.0"/>
   </joint>-->

  <link name="base_link">
  <inertial>
    <origin xyz="0 0 0.125" />
    <mass value="5" />
    <inertia  ixx="0.1" ixy="0.0"  ixz="0.0"  iyy="0.1"  iyz="0.0"  izz="0.1" />
  </inertial>
  <visual>
    <origin xyz="0 0 0.125"/>
    <geometry>
      <box size="0.4 0.2 0.1" />
    </geometry>
  </visual>
  <collision>
    <origin xyz="0 0 0.125"/>
    <geometry>
      <box size="0.4 0.2 0.1" />
    </geometry>
  </collision>
  </link>

  <link name="box">
  <inertial>
    <origin xyz="0 0 0" />
    <mass value="5" />
    <inertia  ixx="0.1" ixy="0.0"  ixz="0.0"  iyy="0.1"  iyz="0.0"  izz="0.1" />
  </inertial>
  <visual>
    <origin xyz="0 0 0"/>
    <geometry>
      <box size="0.3 0.2 0.1" />
    </geometry>
  </visual>
  <collision>
    <origin xyz="0 0 0"/>
    <geometry>
      <box size="0.3 0.2 0.1" />
    </geometry>
  </collision>
  </link>

  <joint name="base_link_box" type="fixed">
    <parent link="base_link"/>
    <child link="box"/>
    <axis xyz="0 0 0"/>
    <origin xyz="-0.05 0 0.225"/>
  </joint>

  <gazebo reference="base_link">
    <material>Gazebo/Blue</material>
  </gazebo>

  <link name="right_wheel">
  <inertial>
    <origin rpy="1.5707963267948966 0 0" xyz="0 0 0" />
    <mass value="0.1" />
    <inertia  ixx="0.01" ixy="0.0"  ixz="0.0"  iyy="0.01"  iyz="0.0"  izz="0.01" />
  </inertial>
  <visual>
    <origin rpy="1.5707963267948966 0 0" xyz="0 0 0"/>
    <geometry>
      <cylinder length="0.05" radius="0.075"/>
    </geometry>
  </visual>
  <collision>
    <origin rpy="1.5707963267948966 0 0" xyz="0 0 0"/>
    <geometry>
      <cylinder length="0.05" radius="0.075"/>
    </geometry>
  </collision>
  </link>

  <gazebo reference="right_wheel">
    <material>Gazebo/Black</material>
  </gazebo>

  <joint name="base_link_right_wheel" type="continuous">
    <parent link="base_link"/>
    <child link="right_wheel"/>
    <axis xyz="0 1 0"/>
    <origin xyz="0.1 -0.15 0.075"/>
  </joint>

  <transmission name="T_base_link_right_wheel">
    <type>transmission_interface/SimpleTransmission</type>
    <actuator name="motor_1">
      <mechanicalReduction>1</mechanicalReduction>
      <hardwareInterface>hardware_interface/VelocityJointInterface</hardwareInterface>
    </actuator>
    <joint name="base_link_right_wheel">
      <hardwareInterface>hardware_interface/VelocityJointInterface</hardwareInterface>
    </joint>
  </transmission>

  <link name="left_wheel">
  <inertial>
    <origin rpy="1.5707963267948966 0 0" xyz="0 0 0" />
    <mass value="0.1" />
    <inertia  ixx="0.01" ixy="0.0"  ixz="0.0"  iyy="0.01"  iyz="0.0"  izz="0.01" />
  </inertial>
  <visual>
    <origin rpy="1.5707963267948966 0 0" xyz="0 0 0"/>
    <geometry>
      <cylinder length="0.05" radius="0.075"/>
    </geometry>
  </visual>
  <collision>
    <origin rpy="1.5707963267948966 0 0" xyz="0 0 0"/>
    <geometry>
      <cylinder length="0.05" radius="0.075"/>
    </geometry>
  </collision>
  </link>

  <gazebo reference="left_wheel">
    <material>Gazebo/Black</material>
  </gazebo>

  <joint name="base_link_left_wheel" type="continuous">
    <parent link="base_link"/>
    <child link="left_wheel"/>
    <axis xyz="0 1 0"/>
    <origin xyz="0.1 0.15 0.075"/>
  </joint>

  <transmission name="T_base_link_left_wheel">
    <type>transmission_interface/SimpleTransmission</type>
    <actuator name="motor_2">
      <mechanicalReduction>1</mechanicalReduction>
      <hardwareInterface>hardware_interface/VelocityJointInterface</hardwareInterface>
    </actuator>
    <joint name="base_link_left_wheel">
      <hardwareInterface>hardware_interface/VelocityJointInterface</hardwareInterface>
    </joint>
  </transmission>

  <link name="back_wheel">
  <inertial>
    <origin rpy="1.5707963267948966 0 0" xyz="0 0 0" />
    <mass value="0.1" />
    <inertia  ixx="0.01" ixy="0.0"  ixz="0.0"  iyy="0.01"  iyz="0.0"  izz="0.01" />
  </inertial>
  <visual>
    <origin rpy="1.5707963267948966 0 0" xyz="0 0 0"/>
    <geometry>
      <sphere length="0.1" radius="0.025"/>
    </geometry>
  </visual>
  <collision>
    <origin rpy="1.5707963267948966 0 0" xyz="0 0 0"/>
    <geometry>
      <sphere length="0.1" radius="0.025"/>
    </geometry>
  </collision>
      <surface>
        <friction>
          <ode>
            <mu>0.01</mu>
            <mu2>0.01</mu2>
          </ode>
        </friction>
      </surface>
  </link>

  <gazebo reference="back_wheel">
    <material>Gazebo/White</material>
  </gazebo>

  <joint name="base_link_back_wheel" type="continuous">
    <parent link="base_link"/>
    <child link="back_wheel"/>
    <axis xyz="0 1 1"/>
    <origin xyz="-0.15 0 0.025"/>
  </joint>

  <!--link name="right_back_wheel">
  <inertial>
    <origin rpy="1.5707963267948966 0 0" xyz="0 0 0" />
    <mass value="0.1" />
    <inertia  ixx="0.01" ixy="0.0"  ixz="0.0"  iyy="0.01"  iyz="0.0"  izz="0.01" />
  </inertial>
  <visual>
    <origin rpy="1.5707963267948966 0 0" xyz="0 0 0"/>
    <geometry>
      <cylinder length="0.05" radius="0.075"/>
    </geometry>
  </visual>
  <collision>
    <origin rpy="1.5707963267948966 0 0" xyz="0 0 0"/>
    <geometry>
      <cylinder length="0.05" radius="0.075"/>
    </geometry>
  </collision>
  </link>

  <gazebo reference="right_back_wheel">
    <material>Gazebo/Black</material>
  </gazebo>

  <joint name="base_link_right_back_wheel" type="continuous">
    <parent link="base_link"/>
    <child link="right_back_wheel"/>
    <axis xyz="0 1 0"/>
    <origin xyz="-0.1 -0.15 0.075"/>
  </joint>

  <transmission name="T_base_link_right_back_wheel">
    <type>transmission_interface/SimpleTransmission</type>
    <actuator name="motor_3">
      <mechanicalReduction>1</mechanicalReduction>
      <hardwareInterface>hardware_interface/VelocityJointInterface</hardwareInterface>
    </actuator>
    <joint name="base_link_right_back_wheel">
      <hardwareInterface>hardware_interface/VelocityJointInterface</hardwareInterface>
    </joint>
  </transmission>

  <link name="left_back_wheel">
  <inertial>
    <origin rpy="1.5707963267948966 0 0" xyz="0 0 0" />
    <mass value="0.1" />
    <inertia  ixx="0.01" ixy="0.0"  ixz="0.0"  iyy="0.01"  iyz="0.0"  izz="0.01" />
  </inertial>
  <visual>
    <origin rpy="1.5707963267948966 0 0" xyz="0 0 0"/>
    <geometry>
      <cylinder length="0.05" radius="0.075"/>
    </geometry>
  </visual>
  <collision>
    <origin rpy="1.5707963267948966 0 0" xyz="0 0 0"/>
    <geometry>
      <cylinder length="0.05" radius="0.075"/>
    </geometry>
  </collision>
  </link>

  <gazebo reference="left_back_wheel">
    <material>Gazebo/Black</material>
  </gazebo>

  <joint name="base_link_left_back_wheel" type="continuous">
    <parent link="base_link"/>
    <child link="left_back_wheel"/>
    <axis xyz="0 1 0"/>
    <origin xyz="-0.1 0.15 0.075"/>
  </joint>

  <transmission name="T_base_link_left_back_wheel">
    <type>transmission_interface/SimpleTransmission</type>
    <actuator name="motor_4">
      <mechanicalReduction>1</mechanicalReduction>
      <hardwareInterface>hardware_interface/VelocityJointInterface</hardwareInterface>
    </actuator>
    <joint name="base_link_left_back_wheel">
      <hardwareInterface>hardware_interface/VelocityJointInterface</hardwareInterface>
    </joint>
  </transmission-->

<gazebo>
  <plugin name="differential_drive_controller" filename="libgazebo_ros_diff_drive.so">
    <alwaysOn>true</alwaysOn>
    <updateRate>10</updateRate>
    <leftJoint>base_link_left_wheel</leftJoint>
    <rightJoint>base_link_right_wheel</rightJoint>
    <wheelSeparation>0.3</wheelSeparation>
    <wheelDiameter>0.15</wheelDiameter>
    <torque>1.41</torque>
    <commandTopic>cmd_vel</commandTopic>
    <odometryTopic>odom</odometryTopic>
    <odometryFrame>odom</odometryFrame>
    <robotBaseFrame>base_link</robotBaseFrame>
    <publishWheelJointState>true</publishWheelJointState>
    <enable_odom_tf>true</enable_odom_tf>
  </plugin>
</gazebo>

  <xacro:include filename="$(find mcl_pi_gazebo)/urdf/hokuyo.xacro"/>
  <xacro:laser name="base_laser" parent="base_link" xyz="0.225 0 0.2" rpy="0 0 0" meshes="package://gazebo_plugins/test/multi_robot_scenario/meshes/laser"/>

</robot>
